<?xml version="1.0"?>
<sdf version='1.6'>

<!-- creating car model-->
  <model name='myfirst1'>
    <!--pose>395 94 0 0 0 -2.83</pose-->
    <pose>0 0 0 0 0 0</pose>
    <link name='base_link'>
      <pose frame=''>0 0 0 0 -0 0</pose>
      <inertial>
        <pose frame=''>0 0 0.4 0 -0 0</pose>
        <mass>1225</mass>
        <inertia>
          <ixx>523.5</ixx>
          <ixy>0</ixy>
          <ixz>0</ixz>
          <iyy>2018</iyy>
          <iyz>0</iyz>
          <izz>2141.38</izz>
        </inertia>
      </inertial>
<!-- collision model from blender -->
      <collision name='base_link_collision'>
        <pose frame=''>0 0 0.6 0 -0 0</pose>
	 <geometry>
          <box>
            <size>4.22 1.78 1</size>
          </box>
        </geometry>
      </collision>
<!--visual model from blender -->
      <visual name='base_link_visual'>
        <pose frame=''>0 0 0.1 0 -0 1.5707</pose>
        <geometry>
          <mesh>
            <scale>1 1 1</scale>
            <uri>model://car/meshes/veloster_shell_optimized_0.4.dae</uri>
          </mesh>
        </geometry>
<plugin name ="libinit_visual_parameters" filename = "libinit_visual_parameters.so"/>
      </visual> 
      <visual name='brake_light_visual'>
        <pose frame=''>0 0 0.1 0 -0 1.5707</pose>
        <geometry>
          <mesh>
            <scale>1 1 1</scale>
            <uri>model://car/meshes/brake_light_optimized_0.4.dae</uri>
          </mesh>
        </geometry>
<plugin name ="brakelight" filename = "libbrake_light.so"/>
      </visual>
      <visual name='right_indicator_visual'>
        <pose frame=''>0 0 0.1 0 -0 1.5707</pose>
        <geometry>
          <mesh>
            <scale>1 1 1</scale>
            <uri>model://car/meshes/indicator_right.dae</uri>
          </mesh>
        </geometry>
<plugin name ="rightindicatorchange" filename = "librightIndicator_change.so"/>
      </visual> 
      <visual name='zleft_indicator_visual'>
        <pose frame=''>0 0 0.1 0 -0 1.5707</pose>
        <geometry>
          <mesh>
            <scale>1 1 1</scale>
            <uri>model://car/meshes/indicator_left.dae</uri>
          </mesh>
        </geometry>
<plugin name ="leftindicatorchange" filename = "libleftIndicator_change.so"/>
      </visual>  
    </link>
    <link name='back_left_wheel_susp'>
      <pose frame=''>-1.37 0.62 0.3 0 -0 0</pose>
      <inertial>
        <pose frame=''>0 0 0 0 -0 0</pose>
        <mass>5</mass>
        <inertia>
          <ixx>0.0697</ixx>
          <ixy>0</ixy>
          <ixz>0.0697</ixz>
          <iyy>0.4</iyy>
          <iyz>0</iyz>
          <izz>0.0625</izz>
        </inertia>
      </inertial>
      <collision name='back_left_wheel_susp_collision'>
        <pose frame=''>0 0 0 0 -0 0</pose>
        <geometry>
          <cylinder>
            <length>0.2</length>
            <radius>0.05</radius>
          </cylinder>
        </geometry>
      </collision>
      <visual name='back_left_wheel_susp_visual'>
        <pose frame=''>0 0 0 0 -0 0</pose>
        <geometry>
          <cylinder>
            <length>0.2</length>
            <radius>0.05</radius>
          </cylinder>
        </geometry>
      </visual>
    </link>
    <joint name='back_left_wheel_susp_joint' type='prismatic'>
      <child>back_left_wheel_susp</child>
      <parent>base_link</parent>
      <axis>
        <xyz>0 0 -1</xyz>
        <limit>
          <lower>-0.07</lower>
          <upper>0.07</upper>
          <effort>1000</effort>
          <velocity>0.5</velocity>
        </limit>
        <dynamics>
          <damping>2</damping>
          <friction>0</friction>
          <spring_reference>0</spring_reference>
          <spring_stiffness>0</spring_stiffness>
        </dynamics>
        <use_parent_model_frame>1</use_parent_model_frame>
      </axis>
    </joint>
    <link name='back_left_wheel'>
      <pose frame=''>-1.37 0.79 0.3 0 -0 0</pose>
      <inertial>
        <pose frame=''>0 0 0 0 -0 0</pose>
        <mass>23</mass>
        <inertia>
          <ixx>0.6512</ixx>
          <ixy>0</ixy>
          <ixz>0</ixz>
          <iyy>0.6512</iyy>
          <iyz>0</iyz>
          <izz>1.1252</izz>
        </inertia>
      </inertial>
      <collision name='back_left_wheel_collision'>
        <pose frame=''>0 0 0 1.5707 -0 0</pose>
        <geometry>
          <cylinder>
            <length>0.195</length>
            <radius>0.300</radius>
          </cylinder>
        </geometry>
      </collision>
      <visual name='back_left_wheel_visual'>
        <pose frame=''>0 0 0 1.5707 -0 0</pose>
        <geometry>
          <mesh>
            <scale>0.1 0.1 0.1</scale>
            <uri>model://car/meshes/veloster_wheel_left_optimized_0.4.dae</uri>
          </mesh>
        </geometry>
      </visual>
    </link>
    <joint name='back_left_wheel_joint' type='revolute'>
	<physics>
          <provide_feedback>true</provide_feedback>
        </physics>
      <child>back_left_wheel</child>
      <parent>back_left_wheel_susp</parent>
      <axis>
        <xyz>0 1 0</xyz>
        <limit>
          <lower>-1e+16</lower>
          <upper>1e+16</upper>
        </limit>
        <dynamics>
          <damping>0.1</damping>
          <friction>20</friction>
          <spring_reference>0</spring_reference>
          <spring_stiffness>0</spring_stiffness>
        </dynamics>
        <use_parent_model_frame>1</use_parent_model_frame>
      </axis>
    </joint>



    <link name='back_right_wheel_susp'>
      <pose frame=''>-1.37 -0.62 0.3 0 -0 0</pose>
      <inertial>
        <pose frame=''>0 0 0 0 -0 0</pose>
        <mass>5</mass>
        <inertia>
          <ixx>0.0697</ixx>
          <ixy>0</ixy>
          <ixz>0.0697</ixz>
          <iyy>0.4</iyy>
          <iyz>0</iyz>
          <izz>0.0625</izz>
        </inertia>
      </inertial>
      <collision name='back_right_wheel_susp_collision'>
        <pose frame=''>0 0 0 0 -0 0</pose>
        <geometry>
          <cylinder>
            <length>0.2</length>
            <radius>0.05</radius>
          </cylinder>
        </geometry>
      </collision>
      <visual name='back_right_wheel_susp_visual'>
        <pose frame=''>0 0 0 0 -0 0</pose>
        <geometry>
          <cylinder>
            <length>0.2</length>
            <radius>0.05</radius>
          </cylinder>
        </geometry>
      </visual>
    </link>
    <joint name='back_right_wheel_susp_joint' type='prismatic'>
      <child>back_right_wheel_susp</child>
      <parent>base_link</parent>
      <axis>
        <xyz>0 0 -1</xyz>
        <limit>
          <lower>-0.07</lower>
          <upper>0.07</upper>
          <effort>1000</effort>
          <velocity>0.5</velocity>
        </limit>
        <dynamics>
          <damping>2</damping>
          <friction>0</friction>
          <spring_reference>0</spring_reference>
          <spring_stiffness>0</spring_stiffness>
        </dynamics>
        <use_parent_model_frame>1</use_parent_model_frame>
      </axis>
    </joint>
    <link name='back_right_wheel'>
      <pose frame=''>-1.37 -0.79 0.3 0 -0 0</pose>
      <inertial>
        <pose frame=''>0 0 0 0 -0 0</pose>
        <mass>23</mass>
        <inertia>
          <ixx>0.6512</ixx>
          <ixy>0</ixy>
          <ixz>0</ixz>
          <iyy>0.6512</iyy>
          <iyz>0</iyz>
          <izz>1.1252</izz>
        </inertia>
      </inertial>
      <collision name='back_right_wheel_collision'>
        <pose frame=''>0 0 0 1.5707 -0 0</pose>
        <geometry>
          <cylinder>
            <length>0.195</length>
            <radius>0.300</radius>
          </cylinder>
        </geometry>
      </collision>
      <visual name='back_right_wheel_visual'>
        <pose frame=''>0 0 0 1.5707 -0 0</pose>
        <geometry>
          <mesh>
            <scale>0.1 0.1 0.1</scale>
            <uri>model://car/meshes/veloster_wheel_right_optimized_0.4.dae</uri>
          </mesh>
        </geometry>
      </visual>
    </link>
    <joint name='back_right_wheel_joint' type='revolute'>
	<physics>
          <provide_feedback>true</provide_feedback>
    	</physics>
      <child>back_right_wheel</child>
      <parent>back_right_wheel_susp</parent>
      <axis>
        <xyz>0 1 0</xyz>
        <limit>
          <lower>-1e+16</lower>
          <upper>1e+16</upper>
        </limit>
        <dynamics>
          <damping>0.1</damping>
          <friction>20</friction>
          <spring_reference>0</spring_reference>
          <spring_stiffness>0</spring_stiffness>
        </dynamics>
        <use_parent_model_frame>1</use_parent_model_frame>
      </axis>
    </joint>



    <link name='front_left_wheel_susp'>
      <pose frame=''>1.26 0.62 0.3 0 -0 0</pose>
      <inertial>
        <pose frame=''>0 0 0 0 -0 0</pose>
        <mass>5</mass>
        <inertia>
          <ixx>0.0697</ixx>
          <ixy>0</ixy>
          <ixz>0.0697</ixz>
          <iyy>0.4</iyy>
          <iyz>0</iyz>
          <izz>0.0625</izz>
        </inertia>
      </inertial>
      <collision name='front_left_wheel_susp_collision'>
        <pose frame=''>0 0 0 0 -0 0</pose>
        <geometry>
          <cylinder>
            <length>0.2</length>
            <radius>0.05</radius>
          </cylinder>
        </geometry>
      </collision>
      <visual name='front_left_wheel_susp_visual'>
        <pose frame=''>0 0 0 0 -0 0</pose>
        <geometry>
          <cylinder>
            <length>0.2</length>
            <radius>0.05</radius>
          </cylinder>
        </geometry>
      </visual>
    </link>
    <joint name='front_left_wheel_susp_joint' type='prismatic'>
      <child>front_left_wheel_susp</child>
      <parent>base_link</parent>
      <axis>
        <xyz>0 0 -1</xyz>
        <limit>
          <lower>-0.07</lower>
          <upper>0.07</upper>
          <effort>1000</effort>
          <velocity>0.5</velocity>
        </limit>
        <dynamics>
          <damping>2</damping>
          <friction>0</friction>
          <spring_reference>0</spring_reference>
          <spring_stiffness>0</spring_stiffness>
        </dynamics>
        <use_parent_model_frame>1</use_parent_model_frame>
      </axis>
    </joint>
    <link name='front_left_steering'>
      <pose frame=''>1.26 0.7 0.3 0 -0 0</pose>
      <inertial>
        <pose frame=''>0 0 0 0 -0 0</pose>
        <mass>5</mass>
        <inertia>
          <ixx>0.0501</ixx>
          <ixy>0</ixy>
          <ixz>0</ixz>
          <iyy>0.0501</iyy>
          <iyz>0</iyz>
          <izz>0.1</izz>
        </inertia>
      </inertial>
      <collision name='front_left_steering_collision'>
        <pose frame=''>0 0 0 1.5707 -0 0</pose>
        <geometry>
          <cylinder>
            <length>0.02</length>
            <radius>0.1</radius>
          </cylinder>
        </geometry>
      </collision>
      <visual name='front_left_steering_visual'>
        <pose frame=''>0 0 0 1.5707 -0 0</pose>
        <geometry>
          <cylinder>
            <length>0.02</length>
            <radius>0.1</radius>
          </cylinder>
        </geometry>
      </visual>
    </link>
    <joint name='front_left_steering_joint' type='revolute'>
	<physics>
          <provide_feedback>true</provide_feedback>
    	</physics>
      <child>front_left_steering</child>
      <parent>front_left_wheel_susp</parent>
      <axis>
        <xyz>0 0 1</xyz>
        <limit>
          <lower>-0.6</lower>
          <upper>0.6</upper>
          <effort>1000</effort>
          <velocity>0.5</velocity>
        </limit>
        <dynamics>
          <spring_reference>0</spring_reference>
          <spring_stiffness>0</spring_stiffness>
        </dynamics>
        <use_parent_model_frame>1</use_parent_model_frame>
      </axis>
    </joint>
    <link name='front_left_wheel'>
      <pose frame=''>1.26 0.78 0.3 0 -0 0</pose>
      <inertial>
        <pose frame=''>0 0 0 0 -0 0</pose>
        <mass>23</mass>
        <inertia>
          <ixx>0.6512</ixx>
          <ixy>0</ixy>
          <ixz>0</ixz>
          <iyy>0.6512</iyy>
          <iyz>0</iyz>
          <izz>1.1252</izz>
        </inertia>
      </inertial>
      <collision name='front_left_wheel_collision'>
        <pose frame=''>0 0 0 1.5707 -0 0</pose>
        <geometry>
          <cylinder>
            <length>0.195</length>
            <radius>0.300</radius>
          </cylinder>
        </geometry>
      </collision>
      <visual name='front_left_wheel_visual'>
        <pose frame=''>0 0 0 1.5707 -0 0</pose>
        <geometry>
          <mesh>
            <scale>0.1 0.1 0.1</scale>
            <uri>model://car/meshes/veloster_wheel_left_optimized_0.4.dae</uri>
          </mesh>
        </geometry>
      </visual>
    </link>
    <joint name='front_left_wheel_joint' type='revolute'>
	<physics>
          <provide_feedback>true</provide_feedback>
    	</physics>
      <child>front_left_wheel</child>
      <parent>front_left_steering</parent>
      <axis>
        <xyz>0 1 0</xyz>
        <limit>
          <lower>-1e+16</lower>
          <upper>1e+16</upper>
        </limit>
        <dynamics>
          <damping>0.1</damping>
          <friction>20</friction>
          <spring_reference>0</spring_reference>
          <spring_stiffness>0</spring_stiffness>
        </dynamics>
        <use_parent_model_frame>1</use_parent_model_frame>
      </axis>
    </joint>




    <link name='front_right_wheel_susp'>
      <pose frame=''>1.26 -0.62 0.3 0 -0 0</pose>
      <inertial>
        <pose frame=''>0 0 0 0 -0 0</pose>
        <mass>5</mass>
        <inertia>
          <ixx>0.0697</ixx>
          <ixy>0</ixy>
          <ixz>0.0697</ixz>
          <iyy>0.4</iyy>
          <iyz>0</iyz>
          <izz>0.0625</izz>
        </inertia>
      </inertial>
      <collision name='front_right_wheel_susp_collision'>
        <pose frame=''>0 0 0 0 -0 0</pose>
        <geometry>
          <cylinder>
            <length>0.2</length>
            <radius>0.05</radius>
          </cylinder>
        </geometry>
      </collision>
      <visual name='front_right_wheel_susp_visual'>
        <pose frame=''>0 0 0 0 -0 0</pose>
        <geometry>
          <cylinder>
            <length>0.2</length>
            <radius>0.05</radius>
          </cylinder>
        </geometry>
      </visual>
    </link>
    <joint name='front_right_wheel_susp_joint' type='prismatic'>
      <child>front_right_wheel_susp</child>
      <parent>base_link</parent>
      <axis>
        <xyz>0 0 -1</xyz>
        <limit>
          <lower>-0.07</lower>
          <upper>0.07</upper>
          <effort>1000</effort>
          <velocity>0.5</velocity>
        </limit>
        <dynamics>
          <damping>2</damping>
          <friction>0</friction>
          <spring_reference>0</spring_reference>
          <spring_stiffness>0</spring_stiffness>
        </dynamics>
        <use_parent_model_frame>1</use_parent_model_frame>
      </axis>
    </joint>
    <link name='front_right_steering'>
      <pose frame=''>1.26 -0.7 0.3 0 -0 0</pose>
      <inertial>
        <pose frame=''>0 0 0 0 -0 0</pose>
        <mass>5</mass>
        <inertia>
          <ixx>0.0501</ixx>
          <ixy>0</ixy>
          <ixz>0</ixz>
          <iyy>0.0501</iyy>
          <iyz>0</iyz>
          <izz>0.1</izz>
        </inertia>
      </inertial>
      <collision name='front_right_steering_collision'>
        <pose frame=''>0 0 0 1.5707 -0 0</pose>
        <geometry>
          <cylinder>
            <length>0.02</length>
            <radius>0.1</radius>
          </cylinder>
        </geometry>
      </collision>
      <visual name='front_right_steering_visual'>
        <pose frame=''>0 0 0 1.5707 -0 0</pose>
        <geometry>
          <cylinder>
            <length>0.02</length>
            <radius>0.1</radius>
          </cylinder>
        </geometry>
      </visual>
    </link>
    <joint name='front_right_steering_joint' type='revolute'>
      <child>front_right_steering</child>
      <parent>front_right_wheel_susp</parent>
      <axis>
        <xyz>0 0 1</xyz>
        <limit>
          <lower>-0.6</lower>
          <upper>0.6</upper>
          <effort>1000</effort>
          <velocity>0.5</velocity>
        </limit>
        <dynamics>
          <spring_reference>0</spring_reference>
          <spring_stiffness>0</spring_stiffness>
        </dynamics>
        <use_parent_model_frame>1</use_parent_model_frame>
      </axis>
    </joint>
    <link name='front_right_wheel'>
      <pose frame=''>1.26 -0.78 0.3 0 -0 0</pose>
      <inertial>
        <pose frame=''>0 0 0 0 -0 0</pose>
        <mass>23</mass>
        <inertia>
          <ixx>0.6512</ixx>
          <ixy>0</ixy>
          <ixz>0</ixz>
          <iyy>0.6512</iyy>
          <iyz>0</iyz>
          <izz>1.1252</izz>
        </inertia>
      </inertial>
      <collision name='front_right_wheel_collision'>
        <pose frame=''>0 0 0 1.5707 -0 0</pose>
        <geometry>
          <cylinder>
            <length>0.195</length>
            <radius>0.300</radius>
          </cylinder>
        </geometry>
      </collision>
      <visual name='front_right_wheel_visual'>
        <pose frame=''>0 0 0 1.5707 -0 0</pose>
        <geometry>
          <mesh>
            <scale>0.1 0.1 0.1</scale>
            <uri>model://car/meshes/veloster_wheel_right_optimized_0.4.dae</uri>
          </mesh>
        </geometry>
      </visual>
    </link>
    <joint name='front_right_wheel_joint' type='revolute'>
	<physics>
          <provide_feedback>true</provide_feedback>
        </physics>
      <child>front_right_wheel</child>
      <parent>front_right_steering</parent>
      <axis>
        <xyz>0 1 0</xyz>
        <limit>
          <lower>-1e+16</lower>
          <upper>1e+16</upper>
        </limit>
        <dynamics>
          <damping>0.1</damping>
          <friction>20</friction>
          <spring_reference>0</spring_reference>
          <spring_stiffness>0</spring_stiffness>
        </dynamics>
        <use_parent_model_frame>1</use_parent_model_frame>
      </axis>
    </joint>


<plugin name = "car_controller" filename = "libcar_controller_plugin_key_input.so"/>
<plugin name = "wheel_speed" filename = "libwheel_plugin.so"/>
<!--plugin name = "car_controller" filename = "libcar_controller_plugin_dbw.so"/-->

  </model>
</sdf>
